<?xml version="1.0" ?>
<!-- =================================================================================== -->
<!-- |    This document was autogenerated by xacro from robot_core.urdf.xacro          | -->
<!-- |    EDITING THIS FILE BY HAND IS NOT RECOMMENDED                                 | -->
<!-- =================================================================================== -->
<robot name="my_rover">
   #1/12
    
  <!-- rover base link -->
  <link name="world"/>
  <joint name="Chassis_joint" type="fixed">
    <parent link="world"/>
    <child link="Chassis"/>
    <origin rpy="0.0 0.0 0.0" xyz="0.0 0.0 0.135"/>
    <axis xyz="0.0 0.0 0.0"/>
  </joint>
  <link name="Chassis">
    <inertial>
      <mass value="0.5"/>
      <origin rpy="0.0 0.0 0.0" xyz="0.0 0.0 0.0"/>
      <!-- refer this "urdf/tutorials/adding physical and collision properties into urdf file" page for the equation -->
      <!-- <inertia ixx="${(constant) * (mass * (height*height + depth*depth))}" ixy="0.0" ixz="0.0" 
                     iyy="${(constant) * (mass * (width*width + depth*depth))}" iyz="0.0" 
                     izz="${(constant) * (mass * (width*width + height*height))}"/> -->
      <inertia ixx="0.007601" ixy="0.0" ixz="0.0" iyy="0.03009" iyz="0.0" izz="0.024365"/>
    </inertial>
    <visual>
      <geometry>
        <box size="0.75 0.4 0.15"/>
      </geometry>
      <material name="">
        <color rgba="1.0 0.3 0.1 1.0"/>
      </material>
    </visual>
    <collision>
      <origin rpy="0.0 0.0 0.0" xyz="0.0 0.0 0.0"/>
      <geometry>
        <box size="0.75 0.4 0.15"/>
      </geometry>
    </collision>
  </link>
  <gazebo reference="Chassis">
    <material> Gazebo/Orange </material>
  </gazebo>
  <!-- camera/sensor mount -->
  <joint name="mount_joint" type="fixed">
    <parent link="Chassis"/>
    <child link="mount_link"/>
    <origin rpy="0.0 0.0 0.0" xyz="0.2 0.0 0.124"/>
    <axis xyz="0.0 0.0 0.0"/>
  </joint>
  <link name="mount_link">
    <inertial>
      <mass value="0.0"/>
      <origin rpy="0.0 0.0 0.0" xyz="0.0 0.0 0.0"/>
      <inertia ixx="0.0" ixy="0.0" ixz="0.0" iyy="0.0" iyz="0.0" izz="0.0"/>
    </inertial>
    <visual>
      <geometry>
        <cylinder length="0.1" radius="0.08"/>
      </geometry>
      <material name="">
        <color rgba="0.0 0.0 0.0 1.0"/>
      </material>
    </visual>
    <collision>
      <origin rpy="0.0 0.0 0.0" xyz="0.0 0.0 0.0"/>
      <geometry>
        <cylinder length="0.1" radius="0.08"/>
      </geometry>
    </collision>
  </link>
  <gazebo reference="mount_link">
    <material> Gazebo/Black</material>
  </gazebo>
  <joint name="front_left_wheel_joint" type="continuous">
    <parent link="Chassis"/>
    <child link="front_left_wheel"/>
    <origin rpy="0.0 0.0 0.0" xyz="0.187 0.25 0.0"/>
    <axis xyz="0.0 1.0 0.0"/>
  </joint>
  <link name="front_left_wheel">
    <inertial>
      <mass value="0.5"/>
      <origin rpy="0.0 0.0 0.0" xyz="0.0 0.0 0.0"/>
      <!-- <inertia ixx="${constant * mass * ((3*radius*radius) + (length*length))}" ixy="0.0" ixz="0.0"
                        iyy="${constant * mass * ((3*radius*radius) + (length*length))}" iyz="0.0"
                        izz="${constant * mass * (radius*radius)}" /> -->
      <inertia ixx="0.00042" ixy="0.0" ixz="0.0" iyy="0.00014" iyz="0.0" izz="0.00063"/>
    </inertial>
    <visual>
      <geometry>
        <mesh filename="package://mobile_robot/meshes/right_tire.stl" scale="0.005 0.005 0.005"/>
         #length = 0.018 radius = &quot;0.066&quot;
                
      </geometry>
      <material name="">
        <color rgba="1.0 0.0 0.0 1.0"/>
      </material>
    </visual>
    <collision>
      <origin rpy="0.0 0.0 0.0" xyz="0.0 0.0 0.0"/>
      <geometry>
        <mesh filename="package://mobile_robot/meshes/right_tire.stl" scale="0.005 0.005 0.005"/>
      </geometry>
    </collision>
  </link>
  <gazebo reference="front_left_wheel">
    <material> Gazebo/Red </material>
    <mu1 value="200.0"/>
    <mu2 value="100.0"/>
    <kp value="10000000.0"/>
    <kd value="1.0"/>
  </gazebo>
  <transmission name="front_left_wheel_trans">
    <type>transmission_interface/SimpleTransmission</type>
    <actuator name="front_left_wheel_motor">
      <mechanicalReduction>1</mechanicalReduction>
    </actuator>
    <joint name="front_left_wheel_joint">
      <hardwareInterface>hardware_interface/VelocityJointInterface</hardwareInterface>
    </joint>
  </transmission>
  <joint name="front_right_wheel_joint" type="continuous">
    <parent link="Chassis"/>
    <child link="front_right_wheel"/>
    <origin rpy="0.0 0.0 0.0" xyz="0.187 -0.25 0.0"/>
    <axis xyz="0.0 1.0 0.0"/>
  </joint>
  <link name="front_right_wheel">
    <inertial>
      <mass value="0.5"/>
      <origin rpy="0.0 0.0 0.0" xyz="0.0 0.0 0.0"/>
      <!-- <inertia ixx="${constant * mass * ((3*radius*radius) + (length*length))}" ixy="0.0" ixz="0.0"
                        iyy="${constant * mass * ((3*radius*radius) + (length*length))}" iyz="0.0"
                        izz="${constant * mass * (radius*radius)}" /> -->
      <inertia ixx="0.00042" ixy="0.0" ixz="0.0" iyy="0.00014" iyz="0.0" izz="0.00063"/>
    </inertial>
    <visual>
      <geometry>
        <mesh filename="package://mobile_robot/meshes/left_tire.stl" scale="0.005 0.005 0.005"/>
         #length = 0.018 radius = &quot;0.066&quot;
                
      </geometry>
      <material name="">
        <color rgba="1.0 0.0 0.0 1.0"/>
      </material>
    </visual>
    <collision>
      <origin rpy="0.0 0.0 0.0" xyz="0.0 0.0 0.0"/>
      <geometry>
        <mesh filename="package://mobile_robot/meshes/left_tire.stl" scale="0.005 0.005 0.005"/>
      </geometry>
    </collision>
  </link>
  <gazebo reference="front_right_wheel">
    <material> Gazebo/Red </material>
    <mu1 value="200.0"/>
    <mu2 value="100.0"/>
    <kp value="10000000.0"/>
    <kd value="1.0"/>
  </gazebo>
  <transmission name="front_right_wheel_trans">
    <type>transmission_interface/SimpleTransmission</type>
    <actuator name="front_right_wheel_motor">
      <mechanicalReduction>1</mechanicalReduction>
    </actuator>
    <joint name="front_right_wheel_joint">
      <hardwareInterface>hardware_interface/VelocityJointInterface</hardwareInterface>
    </joint>
  </transmission>
  <joint name="rear_left_wheel_joint" type="continuous">
    <parent link="Chassis"/>
    <child link="rear_left_wheel"/>
    <origin rpy="0.0 0.0 0.0" xyz="-0.187 0.25 0.0"/>
    <axis xyz="0.0 1.0 0.0"/>
  </joint>
  <link name="rear_left_wheel">
    <inertial>
      <mass value="0.5"/>
      <origin rpy="0.0 0.0 0.0" xyz="0.0 0.0 0.0"/>
      <!-- <inertia ixx="${constant * mass * ((3*radius*radius) + (length*length))}" ixy="0.0" ixz="0.0"
                        iyy="${constant * mass * ((3*radius*radius) + (length*length))}" iyz="0.0"
                        izz="${constant * mass * (radius*radius)}" /> -->
      <inertia ixx="0.00042" ixy="0.0" ixz="0.0" iyy="0.00014" iyz="0.0" izz="0.00063"/>
    </inertial>
    <visual>
      <geometry>
        <mesh filename="package://mobile_robot/meshes/right_tire.stl" scale="0.005 0.005 0.005"/>
         #length = 0.018 radius = &quot;0.066&quot;
                
      </geometry>
      <material name="">
        <color rgba="1.0 0.0 0.0 1.0"/>
      </material>
    </visual>
    <collision>
      <origin rpy="0.0 0.0 0.0" xyz="0.0 0.0 0.0"/>
      <geometry>
        <mesh filename="package://mobile_robot/meshes/right_tire.stl" scale="0.005 0.005 0.005"/>
      </geometry>
    </collision>
  </link>
  <gazebo reference="rear_left_wheel">
    <material> Gazebo/Red </material>
    <mu1 value="200.0"/>
    <mu2 value="100.0"/>
    <kp value="10000000.0"/>
    <kd value="1.0"/>
  </gazebo>
  <transmission name="rear_left_wheel_trans">
    <type>transmission_interface/SimpleTransmission</type>
    <actuator name="rear_left_wheel_motor">
      <mechanicalReduction>1</mechanicalReduction>
    </actuator>
    <joint name="rear_left_wheel_joint">
      <hardwareInterface>hardware_interface/VelocityJointInterface</hardwareInterface>
    </joint>
  </transmission>
  <joint name="rear_right_wheel_joint" type="continuous">
    <parent link="Chassis"/>
    <child link="rear_right_wheel"/>
    <origin rpy="0.0 0.0 0.0" xyz="-0.187 -0.25 0.0"/>
    <axis xyz="0.0 1.0 0.0"/>
  </joint>
  <link name="rear_right_wheel">
    <inertial>
      <mass value="0.5"/>
      <origin rpy="0.0 0.0 0.0" xyz="0.0 0.0 0.0"/>
      <!-- <inertia ixx="${constant * mass * ((3*radius*radius) + (length*length))}" ixy="0.0" ixz="0.0"
                        iyy="${constant * mass * ((3*radius*radius) + (length*length))}" iyz="0.0"
                        izz="${constant * mass * (radius*radius)}" /> -->
      <inertia ixx="0.00042" ixy="0.0" ixz="0.0" iyy="0.00014" iyz="0.0" izz="0.00063"/>
    </inertial>
    <visual>
      <geometry>
        <mesh filename="package://mobile_robot/meshes/left_tire.stl" scale="0.005 0.005 0.005"/>
         #length = 0.018 radius = &quot;0.066&quot;
                
      </geometry>
      <material name="">
        <color rgba="1.0 0.0 0.0 1.0"/>
      </material>
    </visual>
    <collision>
      <origin rpy="0.0 0.0 0.0" xyz="0.0 0.0 0.0"/>
      <geometry>
        <mesh filename="package://mobile_robot/meshes/left_tire.stl" scale="0.005 0.005 0.005"/>
      </geometry>
    </collision>
  </link>
  <gazebo reference="rear_right_wheel">
    <material> Gazebo/Red </material>
    <mu1 value="200.0"/>
    <mu2 value="100.0"/>
    <kp value="10000000.0"/>
    <kd value="1.0"/>
  </gazebo>
  <transmission name="rear_right_wheel_trans">
    <type>transmission_interface/SimpleTransmission</type>
    <actuator name="rear_right_wheel_motor">
      <mechanicalReduction>1</mechanicalReduction>
    </actuator>
    <joint name="rear_right_wheel_joint">
      <hardwareInterface>hardware_interface/VelocityJointInterface</hardwareInterface>
    </joint>
  </transmission>
  <!-- camera/sensor mount -->
  <joint name="lidar_joint" type="fixed">
    <parent link="mount_link"/>
    <child link="lidar_link"/>
    <origin rpy="0.0 0.0 0.0" xyz="0.0 0.0 0.1"/>
    <axis xyz="0.0 0.0 0.0"/>
  </joint>
  <link name="lidar_link">
    <visual>
      <geometry>
        <cylinder length="0.1" radius="0.08"/>
      </geometry>
      <material name="">
        <color rgba="0.0 0.0 0.8 1.0"/>
      </material>
    </visual>
    <collision>
      <origin rpy="0.0 0.0 0.0" xyz="0.0 0.0 0.0"/>
      <geometry>
        <cylinder length="0.1" radius="0.08"/>
      </geometry>
    </collision>
    <inertial>
      <mass value="0.1"/>
      <origin rpy="0.0 0.0 0.0" xyz="0.0 0.0 0.0"/>
      <inertia ixx="0.00024" ixy="0.0" ixz="0.0" iyy="0.00024" iyz="0.0" izz="0.00005"/>
    </inertial>
  </link>
  <gazebo reference="lidar_link">
    <sensor name="head_hokuyo_sensor" type="ray">
      <pose> 0 0 0 0 0 0 </pose>
      <visualize>true</visualize>
      <update_rate>50</update_rate>
      <ray>
        <scan>
          <horizontal>
            <samples>720</samples>
            <resolution>1</resolution>
            <min_angle>-2.356194</min_angle>
            <!-- -135 degrees in radians -->
            <max_angle>2.356194</max_angle>
            <!-- 135 degrees in radians -->
          </horizontal>
        </scan>
        <range>
          <min>0.3</min>
          <!-- Minimum range in meters -->
          <max>15</max>
          <!-- Maximum range in meters -->
          <resolution>0.01</resolution>
          <!-- Range resolution in meters -->
        </range>
      </ray>
      <plugin filename="libgazebo_ros_laser.so" name="gazebo_ros_head_hokuyo_controller">
        <!-- <robotNamespace>my_rover</robotNamespace> -->
        <topicName>/scan</topicName>
        <!-- <ros>
                    <remapping>~/out:=scan</remapping>
                </ros>
                <output_type>sensor_msgs/LaserScan</output_type> -->
        <frameName>lidar_link</frameName>
      </plugin>
    </sensor>
    <material> Gazebo/Blue </material>
  </gazebo>
  <!-- <xacro:include filename="$(find mobile_robot)/description/transmission.urdf"/> -->
  <!-- <xacro:include filename="$(find mobile_robot)/description/gazebo_control.xacro"/> -->
  <gazebo>
    <plugin filename="libgazebo_ros_control.so" name="gazebo_ros_control">
      <robotNamespace>/</robotNamespace>
    </plugin>
  </gazebo>
</robot>
