<?xml version="1.0" ?>
<!-- =================================================================================== -->
<!-- |    This document was autogenerated by xacro from rover.urdf.xacro               | -->
<!-- |    EDITING THIS FILE BY HAND IS NOT RECOMMENDED                                 | -->
<!-- =================================================================================== -->
<robot name="my_rover">
  <!-- Robot Base Link - Chassis -->
  <link name="base_link">
    <!-- Visual representation of the base -->
    <visual>
      <origin rpy="0 0 0" xyz="0 0 0"/>
      <geometry>
        <box size="0.75 0.4 0.15"/>
      </geometry>
      <material name="">
        <color rgba="1.0 0.3 0.1 1.0"/>
      </material>
    </visual>
    <!-- Collision representation of the base (for physics) -->
    <collision>
      <origin rpy="0 0 0" xyz="0 0 0"/>
      <geometry>
        <box size="0.75 0.4 0.15"/>
      </geometry>
    </collision>
    <inertial>
      <mass value="10"/>
      <inertia ixx="1.0" ixy="0.0" ixz="0.0" iyy="1.0" iyz="0.0" izz="1.0"/>
    </inertial>
  </link>
  <gazebo reference="base_link">
    <material> Gazebo/Orange </material>
  </gazebo>
  <!-- camera/sensor/laser mount -->
  <joint name="mount_joint" type="fixed">
    <parent link="base_link"/>
    <child link="mount_link"/>
    <origin rpy="0.0 0.0 0.0" xyz="0.2 0.0 0.28900000000000003"/>
    <axis xyz="0.0 0.0 0.0"/>
  </joint>
  <link name="mount_link">
    <inertial>
      <mass value="0.0"/>
      <origin rpy="0.0 0.0 0.0" xyz="0.0 0.0 0.0"/>
      <inertia ixx="0.0" ixy="0.0" ixz="0.0" iyy="0.0" iyz="0.0" izz="0.0"/>
    </inertial>
    <visual>
      <origin rpy="0.0 0.0 0.0" xyz="0.0 0.0 0.28900000000000003"/>
      <geometry>
        <cylinder length="0.1" radius="0.08"/>
      </geometry>
      <material name="">
        <color rgba="0.0 0.0 0.0 1.0"/>
      </material>
    </visual>
    <collision>
      <origin rpy="0.0 0.0 0.0" xyz="0.0 0.0 0.28900000000000003"/>
      <geometry>
        <cylinder length="0.1" radius="0.08"/>
      </geometry>
    </collision>
  </link>
  <gazebo reference="mount_link">
    <material> Gazebo/Black</material>
  </gazebo>
  <joint name="front_left_wheel_joint" type="continuous">
    <origin rpy="0 0 0" xyz="0.3 0.2 -0.05"/>
    <parent link="base_link"/>
    <child link="front_left_wheel"/>
    <axis xyz="0 1 0"/>
  </joint>
  <!-- Front Right Wheel -->
  <link name="front_left_wheel">
    <visual>
      <origin rpy="0 0 0" xyz="0.3 0.2 -0.05"/>
      <geometry>
        <mesh filename="package://mobile_robot/meshes/left_tire.stl" scale="0.005 0.005 0.005"/>
         #length = 0.018 radius = &quot;0.033&quot;
                
      </geometry>
      <material name="">
        <color rgba="1.0 0.0 0.0 1.0"/>
      </material>
    </visual>
    <collision>
      <origin rpy="0 0 0" xyz="0.3 0.2 -0.05"/>
      <geometry>
        <cylinder length="0.18" radius="0.033"/>
      </geometry>
    </collision>
  </link>
  <gazebo reference="front_left_wheel">
    <material> Gazebo/Red </material>
    <mu1 value="0.001"/>
    <mu2 value="0.001"/>
    <kp value="10000000.0"/>
    <kd value="1.0"/>
  </gazebo>
  <transmission name="front_left_wheel_trans">
    <type>transmission_interface/SimpleTransmission</type>
    <actuator name="front_left_wheel_motor">
      <mechanicalReduction>1</mechanicalReduction>
    </actuator>
    <joint name="front_left_wheel_joint">
      <hardwareInterface>hardware_interface/VelocityJointInterface</hardwareInterface>
    </joint>
  </transmission>
  <joint name="front_right_wheel_joint" type="continuous">
    <origin rpy="0 0 0" xyz="0.3 -0.2 -0.05"/>
    <parent link="base_link"/>
    <child link="front_right_wheel"/>
    <axis xyz="0 1 0"/>
  </joint>
  <!-- Front Right Wheel -->
  <link name="front_right_wheel">
    <visual>
      <origin rpy="0 0 0" xyz="0.3 -0.2 -0.05"/>
      <geometry>
        <mesh filename="package://mobile_robot/meshes/right_tire.stl" scale="0.005 0.005 0.005"/>
         #length = 0.018 radius = &quot;0.033&quot;
                
      </geometry>
      <material name="">
        <color rgba="1.0 0.0 0.0 1.0"/>
      </material>
    </visual>
    <collision>
      <origin rpy="0 0 0" xyz="0.3 -0.2 -0.05"/>
      <geometry>
        <cylinder length="0.18" radius="0.033"/>
      </geometry>
    </collision>
  </link>
  <gazebo reference="front_right_wheel">
    <material> Gazebo/Red </material>
    <mu1 value="0.001"/>
    <mu2 value="0.001"/>
    <kp value="10000000.0"/>
    <kd value="1.0"/>
  </gazebo>
  <transmission name="front_right_wheel_trans">
    <type>transmission_interface/SimpleTransmission</type>
    <actuator name="front_right_wheel_motor">
      <mechanicalReduction>1</mechanicalReduction>
    </actuator>
    <joint name="front_right_wheel_joint">
      <hardwareInterface>hardware_interface/VelocityJointInterface</hardwareInterface>
    </joint>
  </transmission>
  <joint name="rear_left_wheel_joint" type="continuous">
    <origin rpy="0 0 0" xyz="-0.3 0.2 -0.05"/>
    <parent link="base_link"/>
    <child link="rear_left_wheel"/>
    <axis xyz="0 1 0"/>
  </joint>
  <!-- Front Right Wheel -->
  <link name="rear_left_wheel">
    <visual>
      <origin rpy="0 0 0" xyz="-0.3 0.2 -0.05"/>
      <geometry>
        <mesh filename="package://mobile_robot/meshes/left_tire.stl" scale="0.005 0.005 0.005"/>
         #length = 0.018 radius = &quot;0.033&quot;
                
      </geometry>
      <material name="">
        <color rgba="1.0 0.0 0.0 1.0"/>
      </material>
    </visual>
    <collision>
      <origin rpy="0 0 0" xyz="-0.3 0.2 -0.05"/>
      <geometry>
        <cylinder length="0.18" radius="0.033"/>
      </geometry>
    </collision>
  </link>
  <gazebo reference="rear_left_wheel">
    <material> Gazebo/Red </material>
    <mu1 value="0.001"/>
    <mu2 value="0.001"/>
    <kp value="10000000.0"/>
    <kd value="1.0"/>
  </gazebo>
  <transmission name="rear_left_wheel_trans">
    <type>transmission_interface/SimpleTransmission</type>
    <actuator name="rear_left_wheel_motor">
      <mechanicalReduction>1</mechanicalReduction>
    </actuator>
    <joint name="rear_left_wheel_joint">
      <hardwareInterface>hardware_interface/VelocityJointInterface</hardwareInterface>
    </joint>
  </transmission>
  <joint name="rear_right_wheel_joint" type="continuous">
    <origin rpy="0 0 0" xyz="-0.3 -0.2 -0.05"/>
    <parent link="base_link"/>
    <child link="rear_right_wheel"/>
    <axis xyz="0 1 0"/>
  </joint>
  <!-- Front Right Wheel -->
  <link name="rear_right_wheel">
    <visual>
      <origin rpy="0 0 0" xyz="-0.3 -0.2 -0.05"/>
      <geometry>
        <mesh filename="package://mobile_robot/meshes/right_tire.stl" scale="0.005 0.005 0.005"/>
         #length = 0.018 radius = &quot;0.033&quot;
                
      </geometry>
      <material name="">
        <color rgba="1.0 0.0 0.0 1.0"/>
      </material>
    </visual>
    <collision>
      <origin rpy="0 0 0" xyz="-0.3 -0.2 -0.05"/>
      <geometry>
        <cylinder length="0.18" radius="0.033"/>
      </geometry>
    </collision>
  </link>
  <gazebo reference="rear_right_wheel">
    <material> Gazebo/Red </material>
    <mu1 value="0.001"/>
    <mu2 value="0.001"/>
    <kp value="10000000.0"/>
    <kd value="1.0"/>
  </gazebo>
  <transmission name="rear_right_wheel_trans">
    <type>transmission_interface/SimpleTransmission</type>
    <actuator name="rear_right_wheel_motor">
      <mechanicalReduction>1</mechanicalReduction>
    </actuator>
    <joint name="rear_right_wheel_joint">
      <hardwareInterface>hardware_interface/VelocityJointInterface</hardwareInterface>
    </joint>
  </transmission>
</robot>
